<?xml version="1.0" encoding="utf-8"?>
<mujoco model="x1">
  <compiler meshdir="../meshes/" balanceinertia="true"/>

  <!-- Asset Section: Meshes and Materials -->
  <asset>
    <!-- Meshes (unique filenames from URDF) -->
    <mesh name="base_link_simple" file="base_link_simple.STL"/>
    <mesh name="lumber_yaw" file="lumber_yaw.STL"/>
    <mesh name="lumber_roll" file="lumber_roll.STL"/>
    <mesh name="lumber_pitch" file="lumber_pitch.STL"/>
    <mesh name="left_shoulder_pitch" file="left_shoulder_pitch.STL"/>
    <mesh name="left_shoulder_roll" file="left_shoulder_roll.STL"/>
    <mesh name="left_shoulder_yaw" file="left_shoulder_yaw.STL"/>
    <mesh name="left_elbow_pitch" file="left_elbow_pitch.STL"/>
    <mesh name="left_elbow_yaw" file="left_elbow_yaw.STL"/>
    <mesh name="left_wrist_pitch" file="left_wrist_pitch.STL"/>
    <mesh name="right_shoulder_pitch" file="right_shoulder_pitch.STL"/>
    <mesh name="right_shoulder_roll" file="right_shoulder_roll.STL"/>
    <mesh name="right_shoulder_yaw" file="right_shoulder_yaw.STL"/>
    <mesh name="right_elbow_pitch" file="right_elbow_pitch.STL"/>
    <mesh name="right_elbow_yaw" file="right_elbow_yaw.STL"/>
    <mesh name="right_wrist_pitch" file="right_wrist_pitch.STL"/>
    <mesh name="waist_motor_a_link" file="waist_motor_a_link.STL"/>
    <mesh name="waist_motor_a_ball" file="waist_motor_a_ball.STL"/>
    <mesh name="waist_motor_a_loop" file="waist_motor_a_loop.STL"/>
    <mesh name="waist_motor_b_link" file="waist_motor_b_link.STL"/>
    <mesh name="waist_motor_b_ball" file="waist_motor_b_ball.STL"/>
    <mesh name="waist_motor_b_loop" file="waist_motor_b_loop.STL"/>
    <mesh name="left_hip_pitch" file="left_hip_pitch.STL"/>
    <mesh name="left_hip_roll" file="left_hip_roll.STL"/>
    <mesh name="left_hip_yaw" file="left_hip_yaw.STL"/>
    <mesh name="left_knee_pitch" file="left_knee_pitch.STL"/>
    <mesh name="left_ankle_pitch" file="left_ankle_pitch.STL"/>
    <mesh name="left_ankle_roll" file="left_ankle_roll.STL"/>
    <mesh name="leg_l_toe_a_link" file="leg_l_toe_a_link.STL"/>
    <mesh name="leg_l_toe_a_ball" file="leg_l_toe_a_ball.STL"/>
    <mesh name="leg_l_toe_a_loop" file="leg_l_toe_a_loop.STL"/>
    <mesh name="leg_l_toe_b_link" file="leg_l_toe_b_link.STL"/>
    <mesh name="leg_l_toe_b_ball" file="leg_l_toe_b_ball.STL"/>
    <mesh name="leg_l_toe_b_loop" file="leg_l_toe_b_loop.STL"/>
    <mesh name="right_hip_pitch" file="right_hip_pitch.STL"/>
    <mesh name="right_hip_roll" file="right_hip_roll.STL"/>
    <mesh name="right_hip_yaw" file="right_hip_yaw.STL"/>
    <mesh name="right_knee_pitch" file="right_knee_pitch.STL"/>
    <mesh name="right_ankle_pitch" file="right_ankle_pitch.STL"/>
    <mesh name="right_ankle_roll" file="right_ankle_roll.STL"/>
    <mesh name="leg_r_toe_a_link" file="leg_r_toe_a_link.STL"/>
    <mesh name="leg_r_toe_a_ball" file="leg_r_toe_a_ball.STL"/>
    <mesh name="leg_r_toe_a_loop" file="leg_r_toe_a_loop.STL"/>
    <mesh name="leg_r_toe_b_link" file="leg_r_toe_b_link.STL"/>
    <mesh name="leg_r_toe_b_ball" file="leg_r_toe_b_ball.STL"/>
    <mesh name="leg_r_toe_b_loop" file="leg_r_toe_b_loop.STL"/>
    <mesh name="arm_r_wrist_a_ball" file="arm_r_wrist_a_ball.STL"/>
    <mesh name="arm_r_wrist_motor_a_link" file="arm_r_wrist_motor_a_link.STL"/>
    <mesh name="arm_r_wrist_a_loop" file="arm_r_wrist_a_loop.STL"/>
    <mesh name="arm_r_wrist_b_ball" file="arm_r_wrist_b_ball.STL"/>
    <mesh name="arm_r_wrist_motor_b_link" file="arm_r_wrist_motor_b_link.STL"/>
    <mesh name="arm_r_wrist_b_loop" file="arm_r_wrist_b_loop.STL"/>

    <!-- Materials (from URDF <material> tags) -->
    <material name="base_link_material" rgba="0.8 0.4 0 1"/>
    <material name="lumber_yaw_material" rgba="1 0.4 0.4 1"/>
    <material name="lumber_roll_material" rgba="1 0.4 0.4 1"/>
    <material name="lumber_pitch_material" rgba="0.4 1 0.4 1"/>
    <material name="left_shoulder_pitch_material" rgba="1 0.4 0.4 1"/>
    <material name="left_shoulder_roll_material" rgba="1 1 0.4 1"/>
    <material name="left_shoulder_yaw_material" rgba="0.4 1 0.4 1"/>
    <material name="left_elbow_pitch_material" rgba="0 0.5 1 1"/>
    <material name="left_elbow_yaw_material" rgba="0.8 1.0 0.8 1"/>
    <material name="left_wrist_pitch_material" rgba="1 0.5 1 1"/>
    <material name="right_shoulder_pitch_material" rgba="1 0.4 0.4 1"/>
    <material name="right_shoulder_roll_material" rgba="1 0.4 0.4 1"/>
    <material name="right_shoulder_yaw_material" rgba="1 1 0.4 1"/>
    <material name="right_elbow_pitch_material" rgba="0.4 1 0.4 1"/>
    <material name="right_elbow_yaw_material" rgba="0 0.5 1 1"/>
    <material name="right_wrist_pitch_material" rgba="0.8 1.0 0.8 1"/>
    <material name="waist_motor_a_link_material" rgba="0.776470588235294 0.756862745098039 0.737254901960784 1"/>
    <material name="waist_motor_a_ball_material" rgba="0.776470588235294 0.756862745098039 0.737254901960784 1"/>
    <material name="waist_motor_a_loop_material" rgba="1 1 1 1"/>
    <material name="waist_motor_b_link_material" rgba="0.776470588235294 0.756862745098039 0.737254901960784 1"/>
    <material name="waist_motor_b_ball_material" rgba="1 1 1 1"/>
    <material name="waist_motor_b_loop_material" rgba="1 1 1 1"/>
    <material name="left_hip_pitch_material" rgba="1 0.4 0.4 1"/>
    <material name="left_hip_roll_material" rgba="1 1 0.4 1"/>
    <material name="left_hip_yaw_material" rgba="0.4 1 0.4 1"/>
    <material name="left_knee_pitch_material" rgba="0 0.5 1 1"/>
    <material name="left_ankle_pitch_material" rgba="0 0.5 1 1"/>
    <material name="left_ankle_roll_material" rgba="1 0.5 1 1"/>
    <material name="leg_l_toe_a_link_material" rgba="1 1 1 1"/>
    <material name="leg_l_toe_a_ball_material" rgba="1 1 1 1"/>
    <material name="leg_l_toe_a_loop_material" rgba="1 1 1 1"/>
    <material name="leg_l_toe_b_link_material" rgba="1 1 1 1"/>
    <material name="leg_l_toe_b_ball_material" rgba="1 1 1 1"/>
    <material name="leg_l_toe_b_loop_material" rgba="1 1 1 1"/>
    <material name="right_hip_pitch_material" rgba="1 0.4 0.4 1"/>
    <material name="right_hip_roll_material" rgba="1 1 0.4 1"/>
    <material name="right_hip_yaw_material" rgba="0.4 1 0.4 1"/>
    <material name="right_knee_pitch_material" rgba="0 0.5 1 1"/>
    <material name="right_ankle_pitch_material" rgba="0 0.5 1 1"/>
    <material name="right_ankle_roll_material" rgba="1 0.5 1 1"/>
    <material name="leg_r_toe_a_link_material" rgba="1 1 1 1"/>
    <material name="leg_r_toe_a_ball_material" rgba="1 1 1 1"/>
    <material name="leg_r_toe_a_loop_material" rgba="1 1 1 1"/>
    <material name="leg_r_toe_b_link_material" rgba="1 1 1 1"/>
    <material name="leg_r_toe_b_ball_material" rgba="1 1 1 1"/>
    <material name="leg_r_toe_b_loop_material" rgba="1 1 1 1"/>
    <material name="arm_r_wrist_a_ball_material" rgba="1 1 1 1"/>
    <material name="arm_r_wrist_motor_a_link_material" rgba="1 1 1 1"/>
    <material name="arm_r_wrist_a_loop_material" rgba="1 1 1 1"/>
    <material name="arm_r_wrist_b_ball_material" rgba="1 1 1 1"/>
    <material name="arm_r_wrist_motor_b_link_material" rgba="1 1 1 1"/>
    <material name="arm_r_wrist_b_loop_material" rgba="1 1 1 1"/>
  </asset>

  <!-- Worldbody: Kinematic Tree -->
  <worldbody>
    <body name="base_link">
      <inertial pos="0.00252285 -0.00063439 0.03023409" mass="4.3041648" fullinertia="0.02680559 0.01083128 0.02180955 -5.49e-06 5.389e-05 -0.00011229"/>
      <geom type="mesh" mesh="base_link_simple" material="base_link_material" contype="1" conaffinity="1"/>

      <!-- Child: lumber_yaw (revolute) -->
      <body name="lumber_yaw" pos="0.00244999999994827 0 0.115534033809005" quat="0.999999 0 0 -0.0000227457"> <!-- rpy="0 0 -4.549e-05" -->
        <joint type="hinge" axis="0 0 1" pos="0 0 0" limited="true" range="-3.14 3.14"/>
        <inertial pos="-0.01800066 1.4e-06 0.02432982" mass="0.36251906" fullinertia="0.00035849 0.00045823 0.00063906 0 6.896e-05 -1e-08"/>
        <geom type="mesh" mesh="lumber_yaw" material="lumber_yaw_material" contype="0" conaffinity="0"/>
        
        <!-- Child: lumber_roll (revolute) -->
        <body name="lumber_roll" pos="0 0 0.0405" quat="0.5 0.5 -0.5 0"> <!-- rpy="1.5708 0 -1.5708" -->
          <joint type="hinge" axis="0 0 1" pos="0 0 0" limited="true" range="-3.14 3.14"/>
          <inertial pos="-0.00029919 0.0003642 -0.00019197" mass="0.03412073" fullinertia="4.93e-06 5.42e-06 4.83e-06 1.3e-07 0 -9e-08"/>
          <geom type="mesh" mesh="lumber_roll" material="lumber_roll_material" contype="0" conaffinity="0"/>
          
          <!-- Child: lumber_pitch (revolute) -->
          <body name="lumber_pitch" pos="0 0 0" quat="0.7071068 0 0.7071068 0"> <!-- rpy="0 1.5708 0" -->
            <joint type="hinge" axis="0 0 -1" pos="0 0 0" limited="true" range="-3.14 3.14"/>
            <inertial pos="0.00070244 0.21072612 -0.00117164" mass="8.8571074" fullinertia="0.14777412 0.06085873 0.11164753 -0.00392755 0.00035997 -0.00078171"/>
            <geom type="mesh" mesh="lumber_pitch" material="lumber_pitch_material" contype="0" conaffinity="0"/>

            <!-- Child: left_shoulder_pitch (revolute) -->
            <body name="left_shoulder_pitch" pos="0 0.255999999999995 -0.145800000000004" quat="0 0 0 1"> <!-- rpy="0 0 -3.1416" -->
              <joint type="hinge" axis="0 0 -1" pos="0 0 0" limited="true" range="-3.14 3.14"/>
              <inertial pos="-0.00251212 -0.00149141 -0.05674475" mass="1.0067875" fullinertia="0.00108106 0.00096162 0.0008545 2.069e-05 1.583e-05 1.04e-06"/>
              <geom type="mesh" mesh="left_shoulder_pitch" material="left_shoulder_pitch_material" contype="0" conaffinity="0"/>

              <!-- Child: left_shoulder_roll (revolute) -->
              <body name="left_shoulder_roll" pos="-0.0313 0 -0.0592" quat="0 0.7071068 0 -0.7071068"> <!-- rpy="0 -1.5708 0" -->
                <joint type="hinge" axis="0 0 -1" pos="0 0 0" limited="true" range="-3.14 3.14"/>
                <inertial pos="0.000154 0.07784637 -0.02711338" mass="0.69169508" fullinertia="0.00133669 0.00065344 0.00117974 1.21e-06 3.26e-06 9.451e-05"/>
                <geom type="mesh" mesh="left_shoulder_roll" material="left_shoulder_roll_material" contype="0" conaffinity="0"/>

                <!-- Child: left_shoulder_yaw (revolute) -->
                <body name="left_shoulder_yaw" pos="0 0.1252 -0.0313000000000029" quat="0.5 0.5 0.5 0.5"> <!-- rpy="1.5708 1.5708 0" -->
                  <joint type="hinge" axis="0 0 1" pos="0 0 0" limited="true" range="-3.14 3.14"/>
                  <inertial pos="-2.68e-06 0.00182113 -0.00392718" mass="0.72559372" fullinertia="0.00116043 0.00117758 0.00048696 -5.8e-07 1.27e-06 -6.33e-05"/>
                  <geom type="mesh" mesh="left_shoulder_yaw" material="left_shoulder_yaw_material" contype="0" conaffinity="0"/>

                  <!-- Child: left_elbow_pitch (revolute) -->
                  <body name="left_elbow_pitch" pos="0 -0.031 -0.0365000000000021" quat="0 0.7071068 0 0.7071068"> <!-- rpy="-1.5708 0 0" -->
                    <joint type="hinge" axis="0 0 1" pos="0 0 0" limited="true" range="-3.14 3.14"/>
                    <inertial pos="2.604e-05 0.07528242 0.0268658" mass="0.69780135" fullinertia="0.00116267 0.00064619 0.00096882 2.7e-07 1.6e-07 -0.00010622"/>
                    <geom type="mesh" mesh="left_elbow_pitch" material="left_elbow_pitch_material" contype="0" conaffinity="0"/>

                    <!-- Child: left_elbow_yaw (revolute) -->
                    <body name="left_elbow_yaw" pos="0 0.116999999999998 0.0310000000000001" quat="0.5 0.5 -0.5 0.5"> <!-- rpy="1.5708 -1.5708 0" -->
                      <joint type="hinge" axis="0 0 1" pos="0 0 0" limited="true" range="-3.14 3.14"/>
                      <inertial pos="3.656e-5 0.00424199 -0.05421422" mass="0.28787886" fullinertia="0.00071486 0.00069793 0.00054487 9e-08 -3.7e-07 2.677e-05"/>
                      <geom type="mesh" mesh="left_elbow_yaw" material="left_elbow_yaw_material" contype="0" conaffinity="0"/>

                      <!-- Child: left_wrist_pitch (fixed) -->
                      <body name="left_wrist_pitch" pos="0.006 9.9998E-05 -0.1394" quat="0.7071068 0.7071068 0 0"> <!-- rpy="1.5708 0 0" -->
                        <inertial pos="-9.994e-05 0 0.00229425" mass="0.00900738" fullinertia="2.4e-07 5.7e-07 3.8e-07 0 0 0"/>
                        <geom type="mesh" mesh="left_wrist_pitch" material="left_wrist_pitch_material" contype="0" conaffinity="0"/>
                      </body>

                      <!-- Child: arm_l_wrist_a_ball (fixed) -->
                      <body name="arm_l_wrist_a_ball" pos="-0.009 -0.02 -0.0199" quat="0.7071068 0.7071068 0 0"> <!-- rpy="1.5708 0 0" -->
                        <inertial pos="0.00076586 -0.01156825 4.912e-05" mass="0.23598732" fullinertia="7.634e-05 2.519e-05 7.977e-05 1.26e-06 -3e-08 -1e-07"/>
                        <geom type="mesh" mesh="arm_r_wrist_a_ball" material="arm_r_wrist_a_ball_material" contype="0" conaffinity="0"/>

                        <!-- Child: arm_l_wrist_motor_a_link (fixed) -->
                        <body name="arm_l_wrist_motor_a_link" pos="0.0027628 -0.097124 0" quat="0.706587 0.707626 0 0.0142128"> <!-- rpy="1.5708 0 0.028438" -->
                          <inertial pos="0 0 0.00973737" mass="0.00117982" fullinertia="6e-08 8e-08 2e-08 0 0 0"/>
                          <geom type="mesh" mesh="arm_r_wrist_motor_a_link" material="arm_r_wrist_motor_a_link_material" contype="0" conaffinity="0"/>

                          <!-- Child: arm_l_wrist_a_loop (fixed) -->
                          <body name="arm_l_wrist_a_loop" pos="0 0 0.0132" quat="0 -0.707626 0 0.706587"> <!-- rpy="-1.5708 -0.028438 0" -->
                            <inertial pos="0 0 -1.922e-05" mass="0.00548041" fullinertia="8e-08 8e-08 7e-08 0 0 0"/>
                            <geom type="mesh" mesh="arm_r_wrist_a_loop" material="arm_r_wrist_a_loop_material" contype="0" conaffinity="0"/>
                          </body>
                        </body>
                      </body>

                      <!-- Child: arm_l_wrist_b_ball (fixed) -->
                      <body name="arm_l_wrist_b_ball" pos="-0.009 0.02 -0.0199" quat="0 -0.7071068 0 0.7071068"> <!-- rpy="-1.5708 0 0" -->
                        <inertial pos="0.00121967 0.04417257 0" mass="0.03617567" fullinertia="1.73e-05 4.69e-06 1.731e-05 -4.1e-07 0 0"/>
                        <geom type="mesh" mesh="arm_r_wrist_b_ball" material="arm_r_wrist_b_ball_material" contype="0" conaffinity="0"/>

                        <!-- Child: arm_l_wrist_motor_b_link (fixed) -->
                        <body name="arm_l_wrist_motor_b_link" pos="0.0027628 0.097124 0" quat="0 -0.707626 0 -0.706587"> <!-- rpy="-1.5708 0 -0.028438" -->
                          <inertial pos="0.00076586 0.01156825 -4.912e-05" mass="0.23598732" fullinertia="7.634e-05 2.519e-05 7.977e-05 -1.26e-06 3e-08 -1e-07"/>
                          <geom type="mesh" mesh="arm_r_wrist_motor_b_link" material="arm_r_wrist_motor_b_link_material" contype="0" conaffinity="0"/>

                          <!-- Child: arm_l_wrist_b_loop (fixed) -->
                          <body name="arm_l_wrist_b_loop" pos="0 0 0.0132" quat="0.707626 0 -0.706587 0"> <!-- rpy="1.5708 -0.028438 0" -->
                            <inertial pos="0 0 0.00973737" mass="0.00117982" fullinertia="6e-08 8e-08 2e-08 0 0 0"/>
                            <geom type="mesh" mesh="arm_r_wrist_b_loop" material="arm_r_wrist_b_loop_material" contype="0" conaffinity="0"/>
                          </body>
                        </body>
                      </body>
                    </body>
                  </body>
                </body>
              </body>
            </body>

            <!-- Child: right_shoulder_pitch (revolute) -->
            <body name="right_shoulder_pitch" pos="0 0.256 0.1458" quat="0 0 1 0"> <!-- rpy="3.1416 0 0" -->
              <joint type="hinge" axis="0 0 1" pos="0 0 0" limited="true" range="-3.14 3.14"/>
              <inertial pos="0.00250704 -0.00149173 -0.05674328" mass="1.0067875" fullinertia="0.00108106 0.00096162 0.0008545 -2.069e-05 -1.583e-05 8.4e-07"/>
              <geom type="mesh" mesh="right_shoulder_pitch" material="right_shoulder_pitch_material" contype="0" conaffinity="0"/>

              <!-- Child: right_shoulder_roll (revolute) -->
              <body name="right_shoulder_roll" pos="0.0313 0 -0.0592" quat="0 0.7071068 0 0.7071068"> <!-- rpy="3.1416 -1.5708 0" -->
                <joint type="hinge" axis="0 0 1" pos="0 0 0" limited="true" range="-3.14 3.14"/>
                <inertial pos="9.998e-05 -0.07787239 -0.02705625" mass="0.69142604" fullinertia="0.00133757 0.00065281 0.00118057 -3.8e-07 -2.53e-06 -9.481e-05"/>
                <geom type="mesh" mesh="right_shoulder_roll" material="right_shoulder_roll_material" contype="0" conaffinity="0"/>

                <!-- Child: right_shoulder_yaw (revolute) -->
                <body name="right_shoulder_yaw" pos="0 -0.1252 -0.0313" quat="0.7071068 0.7071068 0 0"> <!-- rpy="1.5708 0 0" -->
                  <joint type="hinge" axis="0 0 1" pos="0 0 0" limited="true" range="-3.14 3.14"/>
                  <inertial pos="-0.00189082 -0.00017102 0.03175107" mass="0.604503" fullinertia="0.00050135 0.00055045 0.00049583 2.4e-06 6.05e-06 -1.7e-07"/>
                  <geom type="mesh" mesh="right_shoulder_yaw" material="right_shoulder_yaw_material" contype="0" conaffinity="0"/>

                  <!-- Child: right_elbow_pitch (revolute) -->
                  <body name="right_elbow_pitch" pos="-0.0309999999999999 0 0.0365000000000022" quat="0 -0.5 0 0.5"> <!-- rpy="-1.5708 0 -1.5708" -->
                    <joint type="hinge" axis="0 0 -1" pos="0 0 0" limited="true" range="-3.14 3.14"/>
                    <inertial pos="-2.604e-05 -0.07529828 0.02685625" mass="0.69780135" fullinertia="0.00116302 0.00064594 0.00096939 2.7e-07 -1.6e-07 0.00010623"/>
                    <geom type="mesh" mesh="right_elbow_pitch" material="right_elbow_pitch_material" contype="0" conaffinity="0"/>

                    <!-- Child: right_elbow_yaw (revolute) -->
                    <body name="right_elbow_yaw" pos="0 -0.116999999999998 0.0310000000000001" quat="0 -0.5 0.5 0.5"> <!-- rpy="-1.5708 -1.5708 0" -->
                      <joint type="hinge" axis="0 0 -1" pos="0 0 0" limited="true" range="-3.14 3.14"/>
                      <inertial pos="-3.65e-5 -0.00422926 -0.05414537" mass="0.28835476" fullinertia="0.00071572 0.00069879 0.00054493 9e-08 3.7e-07 -2.692e-05"/>
                      <geom type="mesh" mesh="right_elbow_yaw" material="right_elbow_yaw_material" contype="0" conaffinity="0"/>

                      <!-- Child: right_wrist_pitch (fixed) -->
                      <body name="right_wrist_pitch" pos="0.006 9.9998E-05 -0.1394" quat="0.7071068 0.7071068 0 0"> <!-- rpy="1.5708 0 0" -->
                        <inertial pos="-9.994e-05 0 0.00229425" mass="0.00900738" fullinertia="2.4e-07 5.7e-07 3.8e-07 0 0 0"/>
                        <geom type="mesh" mesh="right_wrist_pitch" material="right_wrist_pitch_material" contype="0" conaffinity="0"/>
                      </body>

                      <!-- Child: arm_r_wrist_a_ball (fixed) -->
                      <body name="arm_r_wrist_a_ball" pos="-0.009 -0.02 -0.0199" quat="0.7071068 0.7071068 0 0"> <!-- rpy="1.5708 0 0" -->
                        <inertial pos="0.00076586 -0.01156825 4.912e-05" mass="0.23598732" fullinertia="7.634e-05 2.519e-05 7.977e-05 1.26e-06 -3e-08 -1e-07"/>
                        <geom type="mesh" mesh="arm_r_wrist_a_ball" material="arm_r_wrist_a_ball_material" contype="0" conaffinity="0"/>

                        <!-- Child: arm_r_wrist_motor_a_link (fixed) -->
                        <body name="arm_r_wrist_motor_a_link" pos="0.0027628 -0.097124 0" quat="0.706587 0.707626 0 0.0142128"> <!-- rpy="1.5708 0 0.028438" -->
                          <inertial pos="0 0 0.00973737" mass="0.00117982" fullinertia="6e-08 8e-08 2e-08 0 0 0"/>
                          <geom type="mesh" mesh="arm_r_wrist_motor_a_link" material="arm_r_wrist_motor_a_link_material" contype="0" conaffinity="0"/>

                          <!-- Child: arm_r_wrist_a_loop (fixed) -->
                          <body name="arm_r_wrist_a_loop" pos="0 0 0.0132" quat="0 -0.707626 0 0.706587"> <!-- rpy="-1.5708 -0.028438 0" -->
                            <inertial pos="0 0 -1.922e-05" mass="0.00548041" fullinertia="8e-08 8e-08 7e-08 0 0 0"/>
                            <geom type="mesh" mesh="arm_r_wrist_a_loop" material="arm_r_wrist_a_loop_material" contype="0" conaffinity="0"/>
                          </body>
                        </body>
                      </body>

                      <!-- Child: arm_r_wrist_b_ball (fixed) -->
                      <body name="arm_r_wrist_b_ball" pos="-0.009 0.02 -0.0199" quat="0 -0.7071068 0 0.7071068"> <!-- rpy="-1.5708 0 0" -->
                        <inertial pos="0.00121967 0.04417257 0" mass="0.03617567" fullinertia="1.73e-05 4.69e-06 1.731e-05 -4.1e-07 0 0"/>
                        <geom type="mesh" mesh="arm_r_wrist_b_ball" material="arm_r_wrist_b_ball_material" contype="0" conaffinity="0"/>

                        <!-- Child: arm_r_wrist_motor_b_link (fixed) -->
                        <body name="arm_r_wrist_motor_b_link" pos="0.0027628 0.097124 0" quat="0 -0.707626 0 -0.706587"> <!-- rpy="-1.5708 0 -0.028438" -->
                          <inertial pos="0 0 0.00973737" mass="0.00117982" fullinertia="6e-08 8e-08 2e-08 0 0 0"/>
                          <geom type="mesh" mesh="arm_r_wrist_motor_b_link" material="arm_r_wrist_motor_b_link_material" contype="0" conaffinity="0"/>

                          <!-- Child: arm_r_wrist_b_loop (fixed) -->
                          <body name="arm_r_wrist_b_loop" pos="0 0 0.0132" quat="0.707626 0 -0.706587 0"> <!-- rpy="1.5708 -0.028438 0" -->
                            <inertial pos="0 0 -1.922e-05" mass="0.00548041" fullinertia="8e-08 8e-08 7e-08 0 0 0"/>
                            <geom type="mesh" mesh="arm_r_wrist_b_loop" material="arm_r_wrist_b_loop_material" contype="0" conaffinity="0"/>
                          </body>
                        </body>
                      </body>
                    </body>
                  </body>
                </body>
              </body>
            </body>

            <!-- Child: waist_motor_a_link (fixed) -->
            <body name="waist_motor_a_link" pos="0 0.0749999999999926 0.0708000000001417" quat="1 0 0 0"> <!-- rpy="0 0 0" -->
              <inertial pos="-0.04046842 0 -0.00673515" mass="0.05818703" fullinertia="1.004e-05 5.053e-05 4.77e-05 -3e-08 -1.16e-05 0"/>
              <geom type="mesh" mesh="waist_motor_a_link" material="waist_motor_a_link_material" contype="0" conaffinity="0"/>

              <!-- Child: waist_motor_a_ball (fixed) -->
              <body name="waist_motor_a_ball" pos="-0.065 0 -0.0108000000001461" quat="0 0 1 0"> <!-- rpy="3.1416 0 0" -->
                <inertial pos="-0.00179727 0.03749978 -3.559e-05" mass="0.03613902" fullinertia="3.412e-05 2.43e-06 3.624e-05 0 0 0"/>
                <geom type="mesh" mesh="waist_motor_a_ball" material="waist_motor_a_ball_material" contype="0" conaffinity="0"/>

                <!-- Child: waist_motor_a_loop (fixed) -->
                <body name="waist_motor_a_loop" pos="0 0.0749999999999924 0" quat="0 0 1 0"> <!-- rpy="3.1416 0 0" -->
                  <inertial pos="0 0 0.00052471" mass="0.01765296" fullinertia="8e-07 8e-07 3.5e-07 0 0 0"/>
                  <geom type="mesh" mesh="waist_motor_a_loop" material="waist_motor_a_loop_material" contype="0" conaffinity="0"/>
                </body>
              </body>
            </body>

            <!-- Child: waist_motor_b_link (fixed) -->
            <body name="waist_motor_b_link" pos="0 0.0750000000000303 -0.0708000000000074" quat="0 0 1 0"> <!-- rpy="3.1416 0 0" -->
              <inertial pos="-0.04046842 0 -0.00673515" mass="0.05818703" fullinertia="1.004e-05 5.053e-05 4.77e-05 -3e-08 -1.16e-05 0"/>
              <geom type="mesh" mesh="waist_motor_b_link" material="waist_motor_b_link_material" contype="0" conaffinity="0"/>

              <!-- Child: waist_motor_b_ball (fixed) -->
              <body name="waist_motor_b_ball" pos="-0.0650000000000492 0 -0.0108000000000005" quat="0 0.7071068 0 0.7071068"> <!-- rpy="3.1416 1.5708 0" -->
                <inertial pos="3.559e-05 -0.03749978 0.00179727" mass="0.03613902" fullinertia="3.624e-05 2.43e-06 3.412e-05 0 0 0"/>
                <geom type="mesh" mesh="waist_motor_b_ball" material="waist_motor_b_ball_material" contype="0" conaffinity="0"/>

                <!-- Child: waist_motor_b_loop (fixed) -->
                <body name="waist_motor_b_loop" pos="0 -0.0749999999999924 0" quat="1 0 0 0"> <!-- rpy="0 0 0" -->
                  <inertial pos="-0.00052471 0 0" mass="0.01765296" fullinertia="3.5e-07 8e-07 8e-07 0 0 0"/>
                  <geom type="mesh" mesh="waist_motor_b_loop" material="waist_motor_b_loop_material" contype="0" conaffinity="0"/>
                </body>
              </body>
            </body>
          </body>
        </body>
      </body>

      <!-- Child: left_hip_pitch (revolute) -->
      <body name="left_hip_pitch" pos="0.00245 0.092277 -0.012143" quat="0.9238795 0 0.3826834 0"> <!-- rpy="0 -0.7854 1.5708" -->
        <joint type="hinge" axis="0 0 1" pos="0 0 0" limited="true" range="-3.14 3.14"/>
        <inertial pos="-4.816e-05 -0.01075844 -0.05407776" mass="1.6733645" fullinertia="0.00234427 0.00252881 0.00218719 -2.8e-06 -8.23e-06 -0.00011548"/>
        <geom type="mesh" mesh="left_hip_pitch" material="left_hip_pitch_material" contype="0" conaffinity="0"/>

        <!-- Child: left_hip_roll (revolute) -->
        <body name="left_hip_roll" pos="0 -0.0405000000000076 -0.0589000000000007" quat="0.6532815 0.6532815 0.2705981 0.2705981"> <!-- rpy="1.5708 0.7854 0" -->
          <joint type="hinge" axis="0 0 -1" pos="0 0 0" limited="true" range="-3.14 3.14"/>
          <inertial pos="0.00014604 -0.04123483 -0.01015339" mass="0.28562185" fullinertia="0.00055729 0.0004105 0.00047775 9.8e-07 5.6e-07 -0.00016545"/>
          <geom type="mesh" mesh="left_hip_roll" material="left_hip_roll_material" contype="0" conaffinity="0"/>

          <!-- Child: left_hip_yaw (revolute) -->
          <body name="left_hip_yaw" pos="0 -0.0838049159474928 -0.0406000000000136" quat="0.7071068 0.7071068 0 0"> <!-- rpy="1.5708 0 0" -->
            <joint type="hinge" axis="0 0 -1" pos="0 0 0" limited="true" range="-3.14 3.14"/>
            <inertial pos="-0.00212295 -3.062e-05 0.09164842" mass="2.7369623" fullinertia="0.01270795 0.01244948 0.00342683 -2.44e-06 0.00060592 4.78e-06"/>
            <geom type="mesh" mesh="left_hip_yaw" material="left_hip_yaw_material" contype="0" conaffinity="0"/>

            <!-- Child: left_knee_pitch (revolute) -->
            <body name="left_knee_pitch" pos="-0.0337000000000097 0 0.142200000000001" quat="0 -0.5 0 0.5"> <!-- rpy="-1.5708 0 -1.5708" -->
              <joint type="hinge" axis="0 0 1" pos="0 0 0" limited="true" range="-3.14 3.14"/>
              <inertial pos="-0.0047354 -0.13101324 0.0279688" mass="1.5122608" fullinertia="0.00806663 0.00174565 0.00825577 -5.703e-05 3.669e-05 0.00090864"/>
              <geom type="mesh" mesh="left_knee_pitch" material="left_knee_pitch_material" contype="0" conaffinity="0"/>

              <!-- Child: left_ankle_pitch (revolute) -->
              <body name="left_ankle_pitch" pos="0 -0.304939999999997 0.0336000000000411" quat="0 0 1 0"> <!-- rpy="-3.1416 0 3.1416" -->
                <joint type="hinge" axis="0 0 -1" pos="0 0 0" limited="true" range="-3.14 3.14"/>
                <inertial pos="-2.32e-06 7.077e-05 -2.048e-05" mass="0.06217211" fullinertia="2.273e-05 2.373e-05 6.68e-06 0 0 0"/>
                <geom type="mesh" mesh="left_ankle_pitch" material="left_ankle_pitch_material" contype="0" conaffinity="0"/>

                <!-- Child: left_ankle_roll (revolute) -->
                <body name="left_ankle_roll" pos="0 0 0" quat="0.7071068 0 0.7071068 0"> <!-- rpy="0 1.5708 0" -->
                  <joint type="hinge" axis="0 0 1" pos="0 0 0" limited="true" range="-3.14 3.14"/>
                  <inertial pos="0.00017156 -0.02524695 -0.00019936" mass="0.58971207" fullinertia="0.00152113 0.00189897 0.00054313 4.7e-07 3.91e-06 4.837e-05"/>
                  <geom type="mesh" mesh="left_ankle_roll" material="left_ankle_roll_material" contype="1" conaffinity="1"/>
                </body>
              </body>

              <!-- Child: leg_l_toe_a_link (fixed) -->
              <body name="leg_l_toe_a_link" pos="0.0198500000000011 -0.109961932116273 0.0336568378288508" quat="0 0.7071068 0 -0.7071068"> <!-- rpy="0 -1.5708 0" -->
                <inertial pos="-0.00875902 0.00339112 -0.00875449" mass="0.03114168" fullinertia="..." /> <!-- Truncated in URDF -->
                <geom type="mesh" mesh="leg_l_toe_a_link" material="leg_l_toe_a_link_material" contype="0" conaffinity="0"/>

                <!-- Child: leg_l_toe_a_ball (fixed) -->
                <body name="leg_l_toe_a_ball" pos="-0.0233806454082247 0.00902193211627456 -0.0211500000000038" quat="1 0 0 0"> <!-- rpy="0 0 0" -->
                  <inertial pos="-1.914e-5 -0.0941377 1.9e-6" mass="0.05674707" fullinertia="0.00022106 1.09e-06 0.00022113 -1e-07 0 -1e-08"/>
                  <geom type="mesh" mesh="leg_l_toe_a_ball" material="leg_l_toe_a_ball_material" contype="0" conaffinity="0"/>

                  <!-- Child: leg_l_toe_a_loop (fixed) -->
                  <body name="leg_l_toe_a_loop" pos="0 -0.195 0" quat="0.7071068 0 0.7071068 0"> <!-- rpy="0 1.5708 0" -->
                    <inertial pos="0 0 -0.0006502" mass="0.0062017" fullinertia="2.8e-07 2.8e-07 1.2e-07 0 0 0"/>
                    <geom type="mesh" mesh="leg_l_toe_a_loop" material="leg_l_toe_a_loop_material" contype="0" conaffinity="0"/>
                  </body>
                </body>
              </body>

              <!-- Child: leg_l_toe_b_link (fixed) -->
              <body name="leg_l_toe_b_link" pos="0.0198499999999967 -0.164961932116271 0.0335431621711256" quat="0 0.7071068 0 -0.7071068"> <!-- rpy="0 -1.5708 0" -->
                <inertial pos="0.0089831 0.00345524 -0.00906395" mass="0.03161" fullinertia="4.6e-06 7.81e-06 8.88e-06 -1.46e-06 1.73e-06 6.7e-07"/>
                <geom type="mesh" mesh="leg_l_toe_b_link" material="leg_l_toe_b_link_material" contype="0" conaffinity="0"/>

                <!-- Child: leg_l_toe_b_ball (fixed) -->
                <body name="leg_l_toe_b_ball" pos="0.0233806454082588 0.00902193211627189 -0.0211500000000081" quat="1 0 0 0"> <!-- rpy="0 0 0" -->
                  <inertial pos="-2.566e-5 -0.06676392 2.566e-5" mass="0.0423305" fullinertia="9.172e-05 9.5e-07 9.179e-05 -7e-08 0 -7e-08"/>
                  <geom type="mesh" mesh="leg_l_toe_b_ball" material="leg_l_toe_b_ball_material" contype="0" conaffinity="0"/>

                  <!-- Child: leg_l_toe_b_loop (fixed) -->
                  <body name="leg_l_toe_b_loop" pos="0 -0.14 0" quat="0.7071068 0 0.7071068 0"> <!-- rpy="0 1.5708 0" -->
                    <inertial pos="0 0 0.00064901" mass="0.0062017" fullinertia="2.8e-07 2.8e-07 1.2e-07 0 0 0"/>
                    <geom type="mesh" mesh="leg_l_toe_b_loop" material="leg_l_toe_b_loop_material" contype="0" conaffinity="0"/>
                  </body>
                </body>
              </body>
            </body>
          </body>
        </body>
      </body>

      <!-- Child: right_hip_pitch (revolute) -->
      <body name="right_hip_pitch" pos="0.00245 -0.092277 -0.012143" quat="0.9238795 0 -0.3826834 0"> <!-- rpy="0 -0.7854 -1.5708" -->
        <joint type="hinge" axis="0 0 1" pos="0 0 0" limited="true" range="-3.14 3.14"/>
        <inertial pos="-0.00011915 0.01061483 -0.05407727" mass="1.6665735" fullinertia="0.00232109 0.00250972 0.00216871 6.27e-06 -4.66e-06 0.00011538"/>
        <geom type="mesh" mesh="right_hip_pitch" material="right_hip_pitch_material" contype="0" conaffinity="0"/>

        <!-- Child: right_hip_roll (revolute) -->
        <body name="right_hip_roll" pos="0 0.0405000000001067 -0.0588999999999981" quat="0.6532815 0.6532815 -0.2705981 -0.2705981"> <!-- rpy="1.5708 0.7854 0" -->
          <joint type="hinge" axis="0 0 1" pos="0 0 0" limited="true" range="-3.14 3.14"/>
          <inertial pos="-0.00027058 -0.04164617 0.01034263" mass="0.28768793" fullinertia="0.0005667 0.00041717 0.00048988 -5.75e-06 2.7e-06 0.00016914"/>
          <geom type="mesh" mesh="right_hip_roll" material="right_hip_roll_material" contype="0" conaffinity="0"/>

          <!-- Child: right_hip_yaw (revolute) -->
          <body name="right_hip_yaw" pos="0 -0.0777549159474913 0.0405999999999983" quat="0.7069896 0.7072237 0 0.00430514"> <!-- rpy="-1.5708 0 0.00861" -->
            <joint type="hinge" axis="0 0 1" pos="0 0 0" limited="true" range="-3.14 3.14"/>
            <inertial pos="-0.00241642 1.672e-05 -0.09704704" mass="2.6963535" fullinertia="0.01254086 0.01225062 0.00336389 -9.4e-07 -0.00059613 -3.99e-06"/>
            <geom type="mesh" mesh="right_hip_yaw" material="right_hip_yaw_material" contype="0" conaffinity="0"/>

            <!-- Child: right_knee_pitch (revolute) -->
            <body name="right_knee_pitch" pos="-0.0347752157308957 0 -0.147956063988164" quat="0 -0.5 0 0.5"> <!-- Approx rpy="1.5794 0 1.5708" -->
              <joint type="hinge" axis="0 0 -1" pos="0 0 0" limited="true" range="-3.14 3.14"/>
              <inertial pos="0.00477062 -0.13172342 0.02793834" mass="1.50954" fullinertia="0.0080222 0.00174185 0.00821165 3.758e-05 -3.424e-05 0.00090582"/>
              <geom type="mesh" mesh="right_knee_pitch" material="right_knee_pitch_material" contype="0" conaffinity="0"/>

              <!-- Child: right_ankle_pitch (revolute) -->
              <body name="right_ankle_pitch" pos="0 -0.304939999999999 0.0335999999999944" quat="0 0 1 0"> <!-- rpy="3.1416 0 0" -->
                <joint type="hinge" axis="0 0 1" pos="0 0 0" limited="true" range="-3.14 3.14"/>
                <inertial pos="2.47e-06 -7.076e-05 -1.763e-05" mass="0.06217211" fullinertia="2.273e-05 2.373e-05 6.68e-06 0 0 -1e-08"/>
                <geom type="mesh" mesh="right_ankle_pitch" material="right_ankle_pitch_material" contype="0" conaffinity="0"/>

                <!-- Child: right_ankle_roll (revolute) -->
                <body name="right_ankle_roll" pos="0 0 0" quat="0.7071068 0 0.7071068 0"> <!-- rpy="0 1.5708 0" -->
                  <joint type="hinge" axis="0 0 1" pos="0 0 0" limited="true" range="-3.14 3.14"/>
                  <inertial pos="-2.32e-06 0.02507893 0.00010556" mass="0.59182763" fullinertia="0.00151845 0.00189242 0.00054401 1e-08 5e-08 -4.706e-05"/>
                  <geom type="mesh" mesh="right_ankle_roll" material="right_ankle_roll_material" contype="1" conaffinity="1"/>
                </body>
              </body>

              <!-- Child: leg_r_toe_a_link (fixed) -->
              <body name="leg_r_toe_a_link" pos="-0.0198500000000012 -0.109961932116264 0.0336568378288726" quat="0.7071068 0 0.7071068 0"> <!-- rpy="0 1.5708 0" -->
                <inertial pos="0.00876658 0.00337152 -0.00875449" mass="0.03114168" fullinertia="4.34e-06 7.47e-06 8.76e-06 -1.43e-06 1.59e-06 6.2e-07"/>
                <geom type="mesh" mesh="leg_r_toe_a_link" material="leg_r_toe_a_link_material" contype="0" conaffinity="0"/>

                <!-- Child: leg_r_toe_a_ball (fixed) -->
                <body name="leg_r_toe_a_ball" pos="0.0233806454082594 0.00902193211626567 -0.0211499999999971" quat="1 0 0 0"> <!-- rpy="0 0 0" -->
                  <inertial pos="-1.914e-5 -0.0941377 1.914e-5" mass="0.05674707" fullinertia="0.00022106 1.09e-06 0.00022113 -1e-07 0 -1e-07"/>
                  <geom type="mesh" mesh="leg_r_toe_a_ball" material="leg_r_toe_a_ball_material" contype="0" conaffinity="0"/>

                  <!-- Child: leg_r_toe_a_loop (fixed) -->
                  <body name="leg_r_toe_a_loop" pos="0 -0.195000000000005 0" quat="0.7071068 0 0.7071068 0"> <!-- rpy="0 1.5708 0" -->
                    <inertial pos="0 0 0.00064901" mass="0.0062017" fullinertia="2.8e-07 2.8e-07 1.2e-07 0 0 0"/>
                    <geom type="mesh" mesh="leg_r_toe_a_loop" material="leg_r_toe_a_loop_material" contype="0" conaffinity="0"/>
                  </body>
                </body>
              </body>

              <!-- Child: leg_r_toe_b_link (fixed) -->
              <body name="leg_r_toe_b_link" pos="-0.0198500000000051 -0.164961932116276 0.0335431621711194" quat="0.7071068 0 0.7071068 0"> <!-- rpy="0 1.5708 0" -->
                <inertial pos="-0.00897565 0.00347454 -0.00906395" mass="0.03161" fullinertia="4.59e-06 7.82e-06 8.88e-06 1.46e-06 -1.73e-06 6.7e-07"/>
                <geom type="mesh" mesh="leg_r_toe_b_link" material="leg_r_toe_b_link_material" contype="0" conaffinity="0"/>

                <!-- Child: leg_r_toe_b_ball (fixed) -->
                <body name="leg_r_toe_b_ball" pos="-0.0233806454082563 0.00902193211627755 -0.0211499999999931" quat="1 0 0 0"> <!-- rpy="0 0 0" -->
                  <inertial pos="-2.566e-5 -0.06676392 2.566e-5" mass="0.0423305" fullinertia="9.172e-05 9.5e-07 9.179e-05 -7e-08 0 -7e-08"/>
                  <geom type="mesh" mesh="leg_r_toe_b_ball" material="leg_r_toe_b_ball_material" contype="0" conaffinity="0"/>

                  <!-- Child: leg_r_toe_b_loop (fixed) -->
                  <body name="leg_r_toe_b_loop" pos="0 -0.14 0" quat="0.7071068 0 0.7071068 0"> <!-- rpy="0 1.5708 0" -->
                    <inertial pos="0 0 -0.00064901" mass="0.0062017" fullinertia="2.8e-07 2.8e-07 1.2e-07 0 0 0"/>
                    <geom type="mesh" mesh="leg_r_toe_b_loop" material="leg_r_toe_b_loop_material" contype="0" conaffinity="0"/>
                  </body>
                </body>
              </body>
            </body>
          </body>
        </body>
      </body>
    </body>
  </worldbody>
</mujoco>